2022-04-06 11:21:06,580   14764     INFO test_runner.py(156) - 预计并发线程数：1
2022-04-06 11:21:06,588   12828     INFO result.py(71) - 开始测试： test_upgrade_fail_1 (on_board_system.test_sros_upgrade.test_sros_upgrade_abnormal_size.TestUpgrade)
2022-04-06 11:21:06,773   12828     INFO logs.py(46) - D:\code\standard_test_1\ST_test_frame\case_data\SROS-v4.17.0-d978eb3-abnormal-size.update
2022-04-06 11:21:06,929   12828     INFO logs.py(46) - 正在上传文件...
2022-04-06 11:21:18,238   12828     INFO logs.py(46) - <class 'web.webapi.OK'>
2022-04-06 11:21:18,577   12828     INFO logs.py(46) - 156
2022-04-06 11:24:46,450   12828     INFO logs.py(46) - 升级结果 0
2022-04-06 11:24:46,547   12828     INFO result.py(158) - 测试执行通过： test_upgrade_fail_1 (on_board_system.test_sros_upgrade.test_sros_upgrade_abnormal_size.TestUpgrade)
2022-04-06 11:24:46,574   12828     INFO result.py(92) - 测试结束： test_upgrade_fail_1 (on_board_system.test_sros_upgrade.test_sros_upgrade_abnormal_size.TestUpgrade)
2022-04-06 11:24:46,606   12828     INFO result.py(93) - 耗时： 219.9573037624359
2022-04-06 11:24:46,637   12828     INFO result.py(71) - 开始测试： test_upgrade_success_1 (on_board_system.test_sros_upgrade.test_sros_upgrade_back_edition.TestUpgrade)
2022-04-06 11:24:46,777   12828     INFO logs.py(46) - D:\code\standard_test_1\ST_test_frame\case_data\SROS-v4.16.0-352fc27.update
2022-04-06 11:24:46,855   12828     INFO logs.py(46) - 正在上传文件...
2022-04-06 11:24:56,700   12828     INFO logs.py(46) - <class 'web.webapi.OK'>
2022-04-06 11:24:57,025   12828     INFO logs.py(46) - 156
2022-04-06 11:25:18,781   12828    ERROR logs.py(55) - ('Connection aborted.', RemoteDisconnected('Remote end closed connection without response'))
2022-04-06 11:25:24,184   12828     INFO logs.py(46) - 升级结束
2022-04-06 11:25:24,293   12828     INFO logs.py(46) - 升级结果 1
2022-04-06 11:25:24,449   12828     INFO result.py(158) - 测试执行通过： test_upgrade_success_1 (on_board_system.test_sros_upgrade.test_sros_upgrade_back_edition.TestUpgrade)
2022-04-06 11:25:24,480   12828     INFO result.py(92) - 测试结束： test_upgrade_success_1 (on_board_system.test_sros_upgrade.test_sros_upgrade_back_edition.TestUpgrade)
2022-04-06 11:25:24,496   12828     INFO result.py(93) - 耗时： 37.82819199562073
2022-04-06 11:25:24,527   12828     INFO result.py(71) - 开始测试： test_upgrade_success_1 (on_board_system.test_sros_upgrade.test_sros_upgrade_completely_upgrade.TestUpgrade)
2022-04-06 11:25:24,729   12828     INFO logs.py(46) - D:\code\standard_test_1\ST_test_frame\case_data\SROS-v4.17.0-d978eb3.update
2022-04-06 11:25:24,932   12828     INFO logs.py(46) - 正在上传文件...
2022-04-06 11:25:35,097   12828     INFO logs.py(46) - <class 'web.webapi.OK'>
2022-04-06 11:25:35,407   12828     INFO logs.py(46) - 157
2022-04-06 11:25:40,736   12828     INFO logs.py(46) - 升级结束
2022-04-06 11:25:40,874   12828     INFO logs.py(46) - 升级结果 1
2022-04-06 11:25:40,956   12828     INFO result.py(158) - 测试执行通过： test_upgrade_success_1 (on_board_system.test_sros_upgrade.test_sros_upgrade_completely_upgrade.TestUpgrade)
2022-04-06 11:25:40,967   12828     INFO result.py(92) - 测试结束： test_upgrade_success_1 (on_board_system.test_sros_upgrade.test_sros_upgrade_completely_upgrade.TestUpgrade)
2022-04-06 11:25:40,998   12828     INFO result.py(93) - 耗时： 16.40898323059082
2022-04-06 11:25:41,014   12828     INFO result.py(71) - 开始测试： test_upgrade_success_1 (on_board_system.test_sros_upgrade.test_sros_upgrade_different_edition.TestUpgrade)
2022-04-06 11:25:41,139   12828     INFO logs.py(46) - D:\code\standard_test_1\ST_test_frame\case_data\SROS-v4.16.0-352fc27.update
2022-04-06 11:25:41,310   12828     INFO logs.py(46) - 正在上传文件...
2022-04-06 11:25:59,674   12828    ERROR result.py(177) - 测试产生错误： test_upgrade_success_1 (on_board_system.test_sros_upgrade.test_sros_upgrade_different_edition.TestUpgrade)
Traceback (most recent call last):
  File "D:\Python\lib\site-packages\urllib3\connectionpool.py", line 703, in urlopen
    httplib_response = self._make_request(
  File "D:\Python\lib\site-packages\urllib3\connectionpool.py", line 449, in _make_request
    six.raise_from(e, None)
  File "<string>", line 3, in raise_from
  File "D:\Python\lib\site-packages\urllib3\connectionpool.py", line 444, in _make_request
    httplib_response = conn.getresponse()
  File "D:\Python\lib\http\client.py", line 1349, in getresponse
    response.begin()
  File "D:\Python\lib\http\client.py", line 316, in begin
    version, status, reason = self._read_status()
  File "D:\Python\lib\http\client.py", line 285, in _read_status
    raise RemoteDisconnected("Remote end closed connection without"
http.client.RemoteDisconnected: Remote end closed connection without response

During handling of the above exception, another exception occurred:

Traceback (most recent call last):
  File "D:\Python\lib\site-packages\requests\adapters.py", line 440, in send
    resp = conn.urlopen(
  File "D:\Python\lib\site-packages\urllib3\connectionpool.py", line 785, in urlopen
    retries = retries.increment(
  File "D:\Python\lib\site-packages\urllib3\util\retry.py", line 550, in increment
    raise six.reraise(type(error), error, _stacktrace)
  File "D:\Python\lib\site-packages\urllib3\packages\six.py", line 769, in reraise
    raise value.with_traceback(tb)
  File "D:\Python\lib\site-packages\urllib3\connectionpool.py", line 703, in urlopen
    httplib_response = self._make_request(
  File "D:\Python\lib\site-packages\urllib3\connectionpool.py", line 449, in _make_request
    six.raise_from(e, None)
  File "<string>", line 3, in raise_from
  File "D:\Python\lib\site-packages\urllib3\connectionpool.py", line 444, in _make_request
    httplib_response = conn.getresponse()
  File "D:\Python\lib\http\client.py", line 1349, in getresponse
    response.begin()
  File "D:\Python\lib\http\client.py", line 316, in begin
    version, status, reason = self._read_status()
  File "D:\Python\lib\http\client.py", line 285, in _read_status
    raise RemoteDisconnected("Remote end closed connection without"
urllib3.exceptions.ProtocolError: ('Connection aborted.', RemoteDisconnected('Remote end closed connection without response'))

During handling of the above exception, another exception occurred:

Traceback (most recent call last):
  File "D:\Python\lib\site-packages\ddt.py", line 191, in wrapper
    return func(self, *args, **kwargs)
  File "D:\code\standard_test_1\ST_test_frame\standard_case\on_board_system\test_sros_upgrade\test_sros_upgrade_different_edition.py", line 58, in test_upgrade_success
    ret = requests.post(request_URL, files=files)
  File "D:\Python\lib\site-packages\requests\api.py", line 117, in post
    return request('post', url, data=data, json=json, **kwargs)
  File "D:\Python\lib\site-packages\requests\api.py", line 61, in request
    return session.request(method=method, url=url, **kwargs)
  File "D:\Python\lib\site-packages\requests\sessions.py", line 529, in request
    resp = self.send(prep, **send_kwargs)
  File "D:\Python\lib\site-packages\requests\sessions.py", line 645, in send
    r = adapter.send(request, **kwargs)
  File "D:\Python\lib\site-packages\requests\adapters.py", line 501, in send
    raise ConnectionError(err, request=request)
requests.exceptions.ConnectionError: ('Connection aborted.', RemoteDisconnected('Remote end closed connection without response'))

2022-04-06 11:25:59,705   12828     INFO result.py(92) - 测试结束： test_upgrade_success_1 (on_board_system.test_sros_upgrade.test_sros_upgrade_different_edition.TestUpgrade)
2022-04-06 11:25:59,721   12828     INFO result.py(93) - 耗时： 18.69072461128235
2022-04-06 11:25:59,752   12828     INFO result.py(71) - 开始测试： test_upgrade_success_1 (on_board_system.test_sros_upgrade.test_sros_upgrade_multiple_model.TestUpgrade)
2022-04-06 11:25:59,892   12828     INFO logs.py(46) - D:\code\standard_test_1\ST_test_frame\case_data\SROS-v4.17.0-d978eb3.update
2022-04-06 11:26:00,078   12828     INFO logs.py(46) - 正在上传文件...
2022-04-06 11:26:02,734   12828    ERROR result.py(177) - 测试产生错误： test_upgrade_success_1 (on_board_system.test_sros_upgrade.test_sros_upgrade_multiple_model.TestUpgrade)
Traceback (most recent call last):
  File "D:\Python\lib\site-packages\urllib3\connection.py", line 174, in _new_conn
    conn = connection.create_connection(
  File "D:\Python\lib\site-packages\urllib3\util\connection.py", line 95, in create_connection
    raise err
  File "D:\Python\lib\site-packages\urllib3\util\connection.py", line 85, in create_connection
    sock.connect(sa)
ConnectionRefusedError: [WinError 10061] 由于目标计算机积极拒绝，无法连接。

During handling of the above exception, another exception occurred:

Traceback (most recent call last):
  File "D:\Python\lib\site-packages\urllib3\connectionpool.py", line 703, in urlopen
    httplib_response = self._make_request(
  File "D:\Python\lib\site-packages\urllib3\connectionpool.py", line 398, in _make_request
    conn.request(method, url, **httplib_request_kw)
  File "D:\Python\lib\site-packages\urllib3\connection.py", line 239, in request
    super(HTTPConnection, self).request(method, url, body=body, headers=headers)
  File "D:\Python\lib\http\client.py", line 1257, in request
    self._send_request(method, url, body, headers, encode_chunked)
  File "D:\Python\lib\http\client.py", line 1303, in _send_request
    self.endheaders(body, encode_chunked=encode_chunked)
  File "D:\Python\lib\http\client.py", line 1252, in endheaders
    self._send_output(message_body, encode_chunked=encode_chunked)
  File "D:\Python\lib\http\client.py", line 1012, in _send_output
    self.send(msg)
  File "D:\Python\lib\http\client.py", line 952, in send
    self.connect()
  File "D:\Python\lib\site-packages\urllib3\connection.py", line 205, in connect
    conn = self._new_conn()
  File "D:\Python\lib\site-packages\urllib3\connection.py", line 186, in _new_conn
    raise NewConnectionError(
urllib3.exceptions.NewConnectionError: <urllib3.connection.HTTPConnection object at 0x000001F541689B50>: Failed to establish a new connection: [WinError 10061] 由于目标计算机积极拒绝，无法连接。

During handling of the above exception, another exception occurred:

Traceback (most recent call last):
  File "D:\Python\lib\site-packages\requests\adapters.py", line 440, in send
    resp = conn.urlopen(
  File "D:\Python\lib\site-packages\urllib3\connectionpool.py", line 785, in urlopen
    retries = retries.increment(
  File "D:\Python\lib\site-packages\urllib3\util\retry.py", line 592, in increment
    raise MaxRetryError(_pool, url, error or ResponseError(cause))
urllib3.exceptions.MaxRetryError: HTTPConnectionPool(host='172.28.1.21', port=80): Max retries exceeded with url: /api/v0/update/import (Caused by NewConnectionError('<urllib3.connection.HTTPConnection object at 0x000001F541689B50>: Failed to establish a new connection: [WinError 10061] 由于目标计算机积极拒绝，无法连接。'))

During handling of the above exception, another exception occurred:

Traceback (most recent call last):
  File "D:\Python\lib\site-packages\ddt.py", line 191, in wrapper
    return func(self, *args, **kwargs)
  File "D:\code\standard_test_1\ST_test_frame\standard_case\on_board_system\test_sros_upgrade\test_sros_upgrade_multiple_model.py", line 53, in test_upgrade_success
    self.upgrade()
  File "D:\code\standard_test_1\ST_test_frame\standard_case\on_board_system\test_sros_upgrade\test_sros_upgrade_multiple_model.py", line 69, in upgrade
    ret = requests.post(request_URL, files=files)
  File "D:\Python\lib\site-packages\requests\api.py", line 117, in post
    return request('post', url, data=data, json=json, **kwargs)
  File "D:\Python\lib\site-packages\requests\api.py", line 61, in request
    return session.request(method=method, url=url, **kwargs)
  File "D:\Python\lib\site-packages\requests\sessions.py", line 529, in request
    resp = self.send(prep, **send_kwargs)
  File "D:\Python\lib\site-packages\requests\sessions.py", line 645, in send
    r = adapter.send(request, **kwargs)
  File "D:\Python\lib\site-packages\requests\adapters.py", line 519, in send
    raise ConnectionError(e, request=request)
requests.exceptions.ConnectionError: HTTPConnectionPool(host='172.28.1.21', port=80): Max retries exceeded with url: /api/v0/update/import (Caused by NewConnectionError('<urllib3.connection.HTTPConnection object at 0x000001F541689B50>: Failed to establish a new connection: [WinError 10061] 由于目标计算机积极拒绝，无法连接。'))

2022-04-06 11:26:02,750   12828     INFO result.py(92) - 测试结束： test_upgrade_success_1 (on_board_system.test_sros_upgrade.test_sros_upgrade_multiple_model.TestUpgrade)
2022-04-06 11:26:02,780   12828     INFO result.py(93) - 耗时： 2.9828450679779053
2022-04-06 11:26:02,811   12828     INFO result.py(71) - 开始测试： test_upgrade_fail_1 (on_board_system.test_sros_upgrade.test_sros_upgrade_offline.TestUpgrade)
2022-04-06 11:26:02,982   12828     INFO logs.py(46) - D:\code\standard_test_1\ST_test_frame\case_data\SROS-v4.17.0-d978eb3-abnormal-size.update
2022-04-06 11:26:03,351   12828     INFO logs.py(46) - 158
2022-04-06 11:26:03,660   13112     INFO logs.py(46) - 正在上传文件...
2022-04-06 11:26:13,799   13112     INFO logs.py(46) - <class 'web.webapi.OK'>
2022-04-06 11:26:19,170   12828     INFO logs.py(46) - 升级结束
2022-04-06 11:26:19,217   12828     INFO logs.py(46) - 升级结果 1
2022-04-06 11:26:19,513   12828  WARNING result.py(192) - 测试未通过： test_upgrade_fail_1 (on_board_system.test_sros_upgrade.test_sros_upgrade_offline.TestUpgrade)
Traceback (most recent call last):
  File "D:\Python\lib\site-packages\ddt.py", line 191, in wrapper
    return func(self, *args, **kwargs)
  File "D:\code\standard_test_1\ST_test_frame\standard_case\on_board_system\test_sros_upgrade\test_sros_upgrade_offline.py", line 85, in test_upgrade_fail
    self.assertEqual(0, result)
AssertionError: 0 != 1

2022-04-06 11:26:19,528   12828     INFO result.py(92) - 测试结束： test_upgrade_fail_1 (on_board_system.test_sros_upgrade.test_sros_upgrade_offline.TestUpgrade)
2022-04-06 11:26:19,559   12828     INFO result.py(93) - 耗时： 16.685270309448242
2022-04-06 11:26:19,589   12828     INFO result.py(71) - 开始测试： test_upgrade_success_1 (on_board_system.test_sros_upgrade.test_sros_upgrade_rename.TestUpgrade)
2022-04-06 11:26:19,591   12828     INFO logs.py(46) - D:\code\standard_test_1\ST_test_frame\case_data\demo-SROS.update
2022-04-06 11:26:19,592   12828     INFO logs.py(46) - 正在上传文件...
2022-04-06 11:26:29,736   12828     INFO logs.py(46) - <class 'web.webapi.OK'>
2022-04-06 11:26:29,802   12828     INFO logs.py(46) - 159
2022-04-06 11:26:34,860   12828     INFO logs.py(46) - 升级结束
2022-04-06 11:26:34,861   12828     INFO logs.py(46) - 升级结果 1
2022-04-06 11:26:34,868   12828     INFO result.py(158) - 测试执行通过： test_upgrade_success_1 (on_board_system.test_sros_upgrade.test_sros_upgrade_rename.TestUpgrade)
2022-04-06 11:26:34,868   12828     INFO result.py(92) - 测试结束： test_upgrade_success_1 (on_board_system.test_sros_upgrade.test_sros_upgrade_rename.TestUpgrade)
2022-04-06 11:26:34,869   12828     INFO result.py(93) - 耗时： 15.278316259384155
2022-04-06 11:26:34,869   14764     INFO test_runner.py(193) - 
Pass	test_upgrade_fail_1 (on_board_system.test_sros_upgrade.test_sros_upgrade_abnormal_size.TestUpgrade)	test_upgrade_fail_1
Pass	test_upgrade_success_1 (on_board_system.test_sros_upgrade.test_sros_upgrade_back_edition.TestUpgrade)	test_upgrade_success_1
Pass	test_upgrade_success_1 (on_board_system.test_sros_upgrade.test_sros_upgrade_completely_upgrade.TestUpgrade)	test_upgrade_success_1
Pass	test_upgrade_success_1 (on_board_system.test_sros_upgrade.test_sros_upgrade_rename.TestUpgrade)	test_upgrade_success_1

2022-04-06 11:26:34,870   14764    ERROR test_runner.py(195) - 
Error	test_upgrade_success_1 (on_board_system.test_sros_upgrade.test_sros_upgrade_different_edition.TestUpgrade)	test_upgrade_success_1
Error	test_upgrade_success_1 (on_board_system.test_sros_upgrade.test_sros_upgrade_multiple_model.TestUpgrade)	test_upgrade_success_1
Fail	test_upgrade_fail_1 (on_board_system.test_sros_upgrade.test_sros_upgrade_offline.TestUpgrade)	test_upgrade_fail_1

2022-04-06 11:26:34,873   14764     INFO test_runner.py(213) - 
测试结束！
运行时间: 0:05:28.452946
共计执行用例数量：7
执行成功用例数量：4
执行失败用例数量：1
跳过执行用例数量：0
产生异常用例数量：2

2022-04-06 11:26:34,875   14764     INFO logs.py(46) - 测试结束，生成基于HTML的测试报告
