2022-03-28 14:57:51,882   12328     INFO test_runner.py(156) - 预计并发线程数：1
2022-03-28 14:57:51,888   13144     INFO result.py(71) - 开始测试： test_upgrade_fail_1 (on_board_system.test_sros_upgrade.test_sros_upgrade_abnormal_size.TestUpgrade)
2022-03-28 14:57:52,296   13144    ERROR result.py(177) - 测试产生错误： test_upgrade_fail_1 (on_board_system.test_sros_upgrade.test_sros_upgrade_abnormal_size.TestUpgrade)
Traceback (most recent call last):
  File "D:\Python\lib\site-packages\ddt.py", line 191, in wrapper
    return func(self, *args, **kwargs)
  File "D:\code\standard_test_1\ST_test_frame\standard_case\on_board_system\test_sros_upgrade\test_sros_upgrade_abnormal_size.py", line 50, in test_upgrade_fail
    self.firmware_path = list(self.base_path.glob(f"**/{self.firmware_name}"))[0]
IndexError: list index out of range

2022-03-28 14:57:52,326   13144     INFO result.py(92) - 测试结束： test_upgrade_fail_1 (on_board_system.test_sros_upgrade.test_sros_upgrade_abnormal_size.TestUpgrade)
2022-03-28 14:57:52,372   13144     INFO result.py(93) - 耗时： 0.40506577491760254
2022-03-28 14:57:52,403   13144     INFO result.py(71) - 开始测试： test_upgrade_success_1 (on_board_system.test_sros_upgrade.test_sros_upgrade_back_edition.TestUpgrade)
2022-03-28 14:57:52,573   13144     INFO logs.py(46) - D:\code\standard_test_1\ST_test_frame\case_data\SROS-v4.16.0-352fc27.update
2022-03-28 14:57:52,650   13144     INFO logs.py(46) - 正在上传文件...
